<?xml version="0.0" ?>
<robot name="spider_robot" xmlns:xacro="http://www.ros.org/wiki/xacro">

    <link name="body">
        <visual>
            <origin xyz="0 0 0.05" rpy="0 0 0"/>
            <geometry>
                <box size="0.5 0.5 1.5" />
            </geometry>
        </visual>
        <collision>
            <origin xyz="0 0 0.05" rpy="0 0 0"/>
            <geometry>
                <box size="1.5 1.0 0.1" />
            </geometry>
        </collision>
        <inertial>
            <origin xyz="0 0 0.05" rpy="0 0 0"/>
            <mass value="0.3" />
            <inertia ixx="0.025" ixy="0.0" ixz="0.0" iyy="0.08" iyz="0.0" izz="0.57" />
        </inertial>

    </link>

    <joint name="joint_1" type="revolute">

        <origin xyz="0 0 0.75"/>
        <parent link="body"/>
        <child link="link_1"/>
        <axis xyz="0 0 1"/>
        <limit lower = "0" upper = "3.14" velocity = "100" efforts = "100" />
    </joint>

    <link name="link_1" >
		<inertial>
				<origin rpy = "0 0 0" xyz = "0 0 0" />
			 <mass value = "0.1" />
			<inertia ixx = "0.02" ixy = "0" ixz = "0" iyy = "0.02" iyz = "0" izz = "0.02" />
		</inertial>
		<collision>
				<origin rpy = "0 1.57 0" xyz = "0.25 0 0" />
			<geometry>
				<capsule length="0.5" radius="0.05"/>
			</geometry>
		</collision>
	</link>

    <joint name="joint_2" type="revolute">

        <origin xyz="0.5 0 0.25"/>
        <parent link="link_1"/>
        <child link="link_2"/>
        <axis xyz="0 0 1"/>
        <limit lower = "0" upper = "3.14" velocity = "100" efforts = "100" />
    </joint>

    <link name="link_2" >
		<inertial>
				<origin rpy = "0 0 0" xyz = "0 0 0" />
			 <mass value = "0.1" />
			<inertia ixx = "0.02" ixy = "0" ixz = "0" iyy = "0.02" iyz = "0" izz = "0.02" />
		</inertial>
		<collision>
				<origin rpy = "0 0 0" xyz = "0 0 0" />
			<geometry>
				<capsule length="0.5" radius="0.05"/>
			</geometry>
		</collision>
	</link>

    <joint name="joint_3" type="revolute">

        <origin xyz="0 0 0.25"/>
        <parent link="link_2"/>
        <child link="link_3"/>
        <axis xyz="1 0 0"/>
        <limit lower = "0" upper = "3.14" velocity = "100" efforts = "100" />
    </joint>

    <link name="link_3" >
		<inertial>
				<origin rpy = "0 0 0" xyz = "0 0 0" />
			 <mass value = "0.1" />
			<inertia ixx = "0.02" ixy = "0" ixz = "0" iyy = "0.02" iyz = "0" izz = "0.02" />
		</inertial>
		<collision>
				<origin rpy = "0 1.57 0" xyz = "-0.1 0 0" />
			<geometry>
				<capsule length="0.2" radius="0.05"/>
			</geometry>
		</collision>
	</link>

    <joint name="joint_4" type="revolute">

        <origin xyz="-0.2 0 0.15"/>
        <parent link="link_3"/>
        <child link="link_4"/>
        <axis xyz="0 0 1"/>
        <limit lower = "0" upper = "3.14" velocity = "100" efforts = "100" />
    </joint>

    <link name="link_4" >
		<inertial>
				<origin rpy = "0 0 0" xyz = "0 0 0" />
			 <mass value = "0.1" />
			<inertia ixx = "0.02" ixy = "0" ixz = "0" iyy = "0.02" iyz = "0" izz = "0.02" />
		</inertial>
		<collision>
				<origin rpy = "0 0 0" xyz = "0 0 0" />
			<geometry>
				<capsule length="0.3" radius="0.05"/>
			</geometry>
		</collision>
    </link>

    <joint name="joint_5" type="revolute">

        <origin xyz="-0.15 0 0.15"/>
        <parent link="link_4"/>
        <child link="link_5"/>
        <axis xyz="0 0 1"/>
        <limit lower = "0" upper = "3.14" velocity = "100" efforts = "100" />
    </joint>

    <link name="link_5" >
		<inertial>
				<origin rpy = "0 0 0" xyz = "0 0 0" />
			 <mass value = "0.1" />
			<inertia ixx = "0.02" ixy = "0" ixz = "0" iyy = "0.02" iyz = "0" izz = "0.02" />
		</inertial>
		<collision>
				<origin rpy = "0 1.57 0" xyz = "0 0 0" />
			<geometry>
				<capsule length="0.3" radius="0.05"/>
			</geometry>
		</collision>
	</link>

    <joint name="joint_6" type="revolute">

        <origin xyz="-0.15 0 0"/>
        <parent link="link_5"/>
        <child link="link_6"/>
        <axis xyz="0 0 1"/>
        <limit lower = "0" upper = "3.14" velocity = "100" efforts = "100" />
    </joint>

    <link name="link_6" >
		<inertial>
			<origin rpy = "0 0 0" xyz = "0 0 0" />
			<mass value = "0.1" />
			<inertia ixx = "0.02" ixy = "0" ixz = "0" iyy = "0.02" iyz = "0" izz = "0.02" />
		</inertial>
		<collision>
				<origin rpy = "0 1.57 " xyz = "0 0 -0.1" />
			<geometry>
				<capsule length="0.2" radius="0.05"/>
			</geometry>
		</collision>
	</link>

    <joint name="joint_7" type="revolute">

        <origin xyz="0 0 0"/>
        <parent link="link_6"/>
        <child link="link_7"/>
        <axis xyz="0 1 0"/>
        <limit lower = "0" upper = "3.14" velocity = "100" efforts = "100" />
    </joint>

    <link name="link_7" >
		<inertial>
			<origin rpy = "0 0 0" xyz = "0 0 0" />
			<mass value = "0.1" />
			<inertia ixx = "0.02" ixy = "0" ixz = "0" iyy = "0.02" iyz = "0" izz = "0.02" />
		</inertial>
		<collision>
				<origin rpy = "0 1.57 0" xyz = "-0.1 0 -0.2" />
			<geometry>
				<capsule length="0.2" radius="0.05"/>
			</geometry>
		</collision>
	</link>

    <joint name="joint_8" type="revolute">

        <origin xyz="0 0 0"/>
        <parent link="link_7"/>
        <child link="link_8"/>
        <axis xyz="1 0 0"/>
        <limit lower = "0" upper = "3.14" velocity = "100" efforts = "100" />
    </joint>

    <link name="link_8" >
        <visual>
            <origin xyz="-0.2 0 -0.4" rpy="0 0 0"/>
            <geometry>
                <box size="0.03 0.4 0.4" />
            </geometry>
        </visual>
        <collision>
            <origin xyz="-0.2 0 -0.4" rpy="0 0 0"/>
            <geometry>
                <box size="0.1 0.1 0.1" />
            </geometry>
        </collision>
        <inertial>
            <origin xyz="0 0 0.05" rpy="0 0 0"/>
            <mass value="0.3" />
            <inertia ixx="0.025" ixy="0.0" ixz="0.0" iyy="0.08" iyz="0.0" izz="0.57" />
        </inertial>
	</link>

</robot>